Workbook
Name healthinsurancepremium: 'employe benefit'!$B$11
Name performancePercentage: salarydata!$AC$2
Name retirementplan: 'employe benefit'!$B$12
Name Slicer_Department: #N/A
Name Slicer_Gender: #N/A
Name Slicer_State: #N/A
Name Slicer_Years__Hire_Date: #N/A
Name tax: 'employe benefit'!$B$9

Sheet Raw data
A1: Employee ID | B1: First Name | C1: Last Name | D1: Department | E1: Gender | F1: Age | G1: State | H1: Hire Date | I1: Phone Number | J1: Basic Salary | K1: Account Number | L1: Bank Name
A2: MDT001 | B2: Daniel | C2: Adewale | D2: ICT | E2: Male | F2: 29 | G2: Lagos | H2: 15/03/2021 | I2: 8000000001 | J2: 450000 | K2: 1 | L2: GTBank
A3: MDT002 | B3: Grace | C3: Okafor | D3: HR | E3: Female | F3: 34 | G3: Anambra | H3: 43746 | I3: 8000000002 | J3: 320000 | K3: 2 | L3: Access Bank
A4: MDT003 | B4: Michael | C4: Ibrahim | D4: Security | E4: Male | F4: 41 | G4: Kaduna | H4: 22/01/2018 | I4: 8000000003 | J4: 280000 | K4: 3 | L4: First Bank
A5: MDT004 | B5: Esther | C5: Balogun | D5: Account | E5: Female | F5: 31 | G5: Ogun | H5: 44687 | I5: 8000000004 | J5: 380000 | K5: 4 | L5: UBA
A6: MDT005 | B6: Samuel | C6: Okoro | D6: Sales | E6: Male | F6: 27 | G6: Enugu | H6: 14/11/2023 | I6: 8000000005 | J6: 300000 | K6: 5 | L6: Zenith Bank
A7: MDT006 | B7: Blessing | C7: Eze | D7: Customer Service | E7: Female | F7: 26 | G7: Imo | H7: 45353 | I7: 8000000006 | J7: 250000 | K7: 6 | L7: Fidelity Bank
A8: MDT007 | B8: David | C8: Yusuf | D8: Marketing | E8: Male | F8: 35 | G8: Kano | H8: 18/09/2020 | I8: 8000000007 | J8: 350000 | K8: 7 | L8: GTBank
A9: MDT008 | B9: Mercy | C9: Johnson | D9: Cleaning | E9: Female | F9: 38 | G9: Lagos | H9: 42920 | I9: 8000000008 | J9: 180000 | K9: 8 | L9: First Bank
A10: MDT009 | B10: Joseph | C10: Adekunle | D10: ICT | E10: Male | F10: 33 | G10: Oyo | H10: 44166 | I10: 8000000009 | J10: 500000 | K10: 9 | L10: Access Bank
A11: MDT010 | B11: Sarah | C11: Mohammed | D11: HR | E11: Female | F11: 30 | G11: Abuja | H11: 25/07/2021 | I11: 8000000010 | J11: 340000 | K11: 10 | L11: UBA
A12: MDT011 | B12: Peter | C12: Nwosu | D12: Account | E12: Male | F12: 42 | G12: Anambra | H12: 16/05/2016 | I12: 8000000011 | J12: 420000 | K12: 11 | L12: Zenith Bank
A13: MDT012 | B13: Janet | C13: Williams | D13: Sales | E13: Female | F13: 28 | G13: Rivers | H13: 20/10/2022 | I13: 8000000012 | J13: 310000 | K13: 12 | L13: GTBank
A14: MDT013 | B14: Victor | C14: Chukwu | D14: Customer Service | E14: Male | F14: 32 | G14: Enugu | H14: 44503 | I14: 8000000013 | J14: 270000 | K14: 13 | L14: Access Bank
A15: MDT014 | B15: Aisha | C15: Bello | D15: Marketing | E15: Female | F15: 29 | G15: Kaduna | H15: 44785 | I15: 8000000014 | J15: 330000 | K15: 14 | L15: First Bank
A16: MDT015 | B16: Emmanuel | C16: Obi | D16: Security | E16: Male | F16: 45 | G16: Imo | H16: 19/06/2015 | I16: 8000000015 | J16: 300000 | K16: 15 | L16: UBA
A17: MDT016 | B17: Favour | C17: Daniel | D17: Cleaning | E17: Female | F17: 36 | G17: Delta | H17: 13/08/2019 | I17: 8000000016 | J17: 190000 | K17: 16 | L17: Fidelity Bank
A18: MDT017 | B18: Andrew | C18: Musa | D18: ICT | E18: Male | F18: 37 | G18: Kaduna | H18: 43557 | I18: 8000000017 | J18: 550000 | K18: 17 | L18: Zenith Bank
A19: MDT018 | B19: Rita | C19: Ojo | D19: HR | E19: Female | F19: 39 | G19: Lagos | H19: 17/09/2017 | I19: 8000000018 | J19: 360000 | K19: 18 | L19: GTBank
A20: MDT019 | B20: Benjamin | C20: Umeh | D20: Account | E20: Male | F20: 29 | G20: Abia | H20: 21/01/2023 | I20: 8000000019 | J20: 390000 | K20: 19 | L20: Access Bank
A21: MDT020 | B21: Helen | C21: Adeyemi | D21: Sales | E21: Female | F21: 33 | G21: Oyo | H21: 44079 | I21: 8000000020 | J21: 325000 | K21: 20 | L21: UBA
A22: MDT021 | B22: Francis | C22: Okeke | D22: Customer Service | E22: Male | F22: 31 | G22: Anambra | H22: 15/10/2021 | I22: 8000000021 | J22: 285000 | K22: 21 | L22: First Bank
A23: MDT022 | B23: Linda | C23: Ibrahim | D23: Marketing | E23: Female | F23: 27 | G23: Kano | H23: 45446 | I23: 8000000022 | J23: 310000 | K23: 22 | L23: Zenith Bank
A24: MDT023 | B24: Isaac | C24: Lawal | D24: Security | E24: Male | F24: 40 | G24: Kwara | H24: 43441 | I24: 8000000023 | J24: 290000 | K24: 23 | L24: GTBank
A25: MDT024 | B25: Comfort | C25: Essien | D25: Cleaning | E25: Female | F25: 44 | G25: Akwa Ibom | H25: 23/02/2016 | I25: 8000000024 | J25: 200000 | K25: 24 | L25: Access Bank
A26: MDT025 | B26: Christopher | C26: George | D26: ICT | E26: Male | F26: 30 | G26: Rivers | H26: 14/08/2022 | I26: 8000000025 | J26: 480000 | K26: 25 | L26: UBA
A27: MDT026 | B27: Patience | C27: Eze | D27: HR | E27: Female | F27: 35 | G27: Imo | H27: 30/11/2019 | I27: 8000000026 | J27: 370000 | K27: 26 | L27: Fidelity Bank
A28: MDT027 | B28: Timothy | C28: Adebayo | D28: Account | E28: Male | F28: 28 | G28: Ogun | H28: 18/04/2023 | I28: 8000000027 | J28: 400000 | K28: 27 | L28: Zenith Bank
A29: MDT028 | B29: Sharon | C29: James | D29: Sales | E29: Female | F29: 32 | G29: Lagos | H29: 44440 | I29: 8000000028 | J29: 315000 | K29: 28 | L29: GTBank
A30: MDT029 | B30: Gabriel | C30: Sunday | D30: Customer Service | E30: Male | F30: 26 | G30: Edo | H30: 16/06/2024 | I30: 8000000029 | J30: 260000 | K30: 29 | L30: Access Bank
A31: MDT030 | B31: Naomi | C31: Abubakar | D31: Marketing | E31: Female | F31: 37 | G31: Kaduna | H31: 43230 | I31: 8000000030 | J31: 345000 | K31: 30 | L31: First Bank
A32: MDT031 | B32: Stephen | C32: Okafor | D32: Security | E32: Male | F32: 39 | G32: Enugu | H32: 44137 | I32: 8000000031 | J32: 305000 | K32: 31 | L32: UBA
A33: MDT032 | B33: Rebecca | C33: Samuel | D33: Cleaning | E33: Female | F33: 30 | G33: Plateau | H33: 22/09/2021 | I33: 8000000032 | J33: 185000 | K33: 32 | L33: Fidelity Bank
A34: MDT033 | B34: Anthony | C34: Obi | D34: ICT | E34: Male | F34: 43 | G34: Anambra | H34: 17/05/2016 | I34: 8000000033 | J34: 600000 | K34: 33 | L34: Zenith Bank
A35: MDT034 | B35: Florence | C35: Musa | D35: HR | E35: Female | F35: 28 | G35: Kano | H35: 44988 | I35: 8000000034 | J35: 350000 | K35: 34 | L35: GTBank
A36: MDT035 | B36: Charles | C36: Bello | D36: Account | E36: Male | F36: 36 | G36: Kaduna | H36: 14/07/2019 | I36: 8000000035 | J36: 435000 | K36: 35 | L36: Access Bank
A37: MDT036 | B37: Susan | C37: Adeola | D37: Sales | E37: Female | F37: 41 | G37: Ogun | H37: 25/01/2017 | I37: 8000000036 | J37: 340000 | K37: 36 | L37: First Bank
A38: MDT037 | B38: Richard | C38: Eze | D38: Customer Service | E38: Male | F38: 34 | G38: Abia | H38: 44110 | I38: 8000000037 | J38: 295000 | K38: 37 | L38: UBA
A39: MDT038 | B39: Caroline | C39: Yusuf | D39: Marketing | E39: Female | F39: 31 | G39: Kano | H39: 19/08/2022 | I39: 8000000038 | J39: 360000 | K39: 38 | L39: Zenith Bank
A40: MDT039 | B40: Matthew | C40: Johnson | D40: Security | E40: Male | F40: 46 | G40: Lagos | H40: 42189 | I40: 8000000039 | J40: 315000 | K40: 39 | L40: GTBank
...

Sheet basicsalarybydepartment
A3: Row Labels | B3: Sum of Basic Salary
A4: ICT | B4: 3680000
A5: HR | B5: 2485000
A6: Account | B6: 2435000
A7: Marketing | B7: 2070000
A8: Sales | B8: 1915000
A9: Security | B9: 1810000
A10: Customer Service | B10: 1665000
A11: Cleaning | B11: 1160000
A12: Grand Total | B12: 17220000

Sheet net salary by department
A3: Row Labels | B3: Sum of -NET SALARY
A4: ICT | B4: 4232000
A5: HR | B5: 2857750
A6: Account | B6: 2800250
A7: Marketing | B7: 2380500
A8: Sales | B8: 2202250
A9: Security | B9: 2081500
A10: Customer Service | B10: 1914750
A11: Cleaning | B11: 1334000
A12: Grand Total | B12: 19803000

Sheet AVERAGE BASIC SALARY BY YEARS O
A3: Row Labels | B3: Average of Basic Salary
A4: 2016 | B4: 406666.67
A5: 2022 | B5: 378333.33
A6: 2019 | B6: 361666.67
A7: 2020 | B7: 359285.71
A8: 2023 | B8: 353000
A9: 2018 | B9: 340000
A10: 2021 | B10: 320625
A11: 2017 | B11: 316000
A12: 2015 | B12: 307500
A13: 2024 | B13: 273333.33
A14: Grand Total | B14: 344400

Sheet LOAN DEDUCTION
A3: Row Labels | B3: Sum of - Loan(1%) | C3: Sum of - Tax(5%) | D3: Sum of - Health Insurance Premium(2%) | E3: Sum of - Retirement Plan(2%)
A4: ICT | B4: 36800 | C4: 184000 | D4: 73600 | E4: 73600
A5: HR | B5: 24850 | C5: 124250 | D5: 49700 | E5: 49700
A6: Account | B6: 24350 | C6: 121750 | D6: 48700 | E6: 48700
A7: Marketing | B7: 20700 | C7: 103500 | D7: 41400 | E7: 41400
A8: Sales | B8: 19150 | C8: 95750 | D8: 38300 | E8: 38300
A9: Security | B9: 18100 | C9: 90500 | D9: 36200 | E9: 36200
A10: Customer Service | B10: 16650 | C10: 83250 | D10: 33300 | E10: 33300
A11: Cleaning | B11: 11600 | C11: 58000 | D11: 23200 | E11: 23200
A12: Grand Total | B12: 172200 | C12: 861000 | D12: 344400 | E12: 344400

Sheet BASIC AND NET SALARY BY DEPARTM
A3: Row Labels | B3: Sum of Basic Salary | C3: Sum of -NET SALARY
A4: ICT | B4: 3680000 | C4: 4232000
A5: HR | B5: 2485000 | C5: 2857750
A6: Account | B6: 2435000 | C6: 2800250
A7: Marketing | B7: 2070000 | C7: 2380500
A8: Sales | B8: 1915000 | C8: 2202250
A9: Security | B9: 1810000 | C9: 2081500
A10: Customer Service | B10: 1665000 | C10: 1914750
A11: Cleaning | B11: 1160000 | C11: 1334000
A12: Grand Total | B12: 17220000 | C12: 19803000

Sheet pivot
A3: Average of Basic Salary | B3: Count of Employee ID | C3: Sum of -NET SALARY | D3: Sum of - Gross Salary | E3: Sum of -Total DEDUCTION.
A4: 344400 | B4: 50 | C4: 19803000 | D4: 21525000 | E4: 1722000

Sheet Salary by gender
A3: Row Labels | B3: Average of Basic Salary
A4: Female | B4: 304400
A5: Male | B5: 384400
A6: Grand Total | B6: 344400

Sheet salarydata
A1: Employee ID | B1: First Name | C1: Last Name | D1: Department | E1: Gender | F1: Age | G1: State | H1: Hire Date | I1: Phone Number | J1: Basic Salary | K1: Account Number | L1: Bank Name | M1: -Performance Bonus (1%) | N1: - House Allowance (15%) | O1: - Transport Allowance (5%) | P1: - wordrope Allowance (2%) | Q1: - Over Time(2%) | R1: - Gross Salary | S1: - Loan(1%) | T1: - Tax(5%) | U1: - Health Insurance Premium(2%) | V1: - Retirement Plan(2%) | W1: -Total DEDUCTION. | X1: -NET SALARY | Y1: employee tenure | AB1: employe benefits | AC1: Column1
A2: MDT008 | B2: Mercy | C2: Johnson | D2: Cleaning | E2: Female | F2: 38 | G2: Lagos | H2: 42920 | I2: 8000000008 | J2: 180000 | K2: 8 | L2: First Bank | M2: =salarydata[[#This Row],[Basic Salary]]*$AC$13 -> 1800 | N2: =salarydata[[#This Row],[Basic Salary]]*$AC$14 -> 27000 | O2: =salarydata[[#This Row],[Basic Salary]]*$AC$15 -> 9000 | P2: =salarydata[[#This Row],[Basic Salary]]*$AC$16 -> 3600 | Q2: =salarydata[[#This Row],[Basic Salary]]*$AC$17 -> 3600 | R2: =salarydata[[#This Row],[Basic Salary]]+salarydata[[#This Row],[ -Performance Bonus (1%)]]+salarydata[[#This Row],[- House Allowance (15%)]]+salarydata[[#This Row],[- Transport Allowance (5%)]]+salarydata[[#This Row],[- wordrope Allowance (2%)]]+salarydata[[#This Row],[- Over Time(2%)]] -> 225000 | S2: =salarydata[[#This Row],[Basic Salary]]*$AC$19 -> 1800 | T2: =salarydata[[#This Row],[Basic Salary]]*tax -> 9000 | U2: =salarydata[[#This Row],[Basic Salary]]*healthinsurancepremium -> 3600 | V2: =salarydata[[#This Row],[Basic Salary]]*retirementplan -> 3600 | W2: =salarydata[[#This Row],[- Loan(1%)]]+salarydata[[#This Row],[- Tax(5%)]]+salarydata[[#This Row],[ - Health Insurance Premium(2%)]]+salarydata[[#This Row],[ - Retirement Plan(2%)]] -> 18000 | X2: =salarydata[[#This Row],[- Gross Salary]]-salarydata[[#This Row],[-Total DEDUCTION.]] -> 207000 | Y2: =DATEDIF(salarydata[[#This Row],[Hire Date]], TODAY(), "Y") -> 9 | AB2: -Performance Bonus (1%) | AC2: 0.01
A3: MDT032 | B3: Rebecca | C3: Samuel | D3: Cleaning | E3: Female | F3: 30 | G3: Plateau | H3: 44461 | I3: 8000000032 | J3: 185000 | K3: 32 | L3: Fidelity Bank | M3: =salarydata[[#This Row],[Basic Salary]]*$AC$13 -> 1850 | N3: =salarydata[[#This Row],[Basic Salary]]*$AC$14 -> 27750 | O3: =salarydata[[#This Row],[Basic Salary]]*$AC$15 -> 9250 | P3: =salarydata[[#This Row],[Basic Salary]]*$AC$16 -> 3700 | Q3: =salarydata[[#This Row],[Basic Salary]]*$AC$17 -> 3700 | R3: =salarydata[[#This Row],[Basic Salary]]+salarydata[[#This Row],[ -Performance Bonus (1%)]]+salarydata[[#This Row],[- House Allowance (15%)]]+salarydata[[#This Row],[- Transport Allowance (5%)]]+salarydata[[#This Row],[- wordrope Allowance (2%)]]+salarydata[[#This Row],[- Over Time(2%)]] -> 231250 | S3: =salarydata[[#This Row],[Basic Salary]]*$AC$19 -> 1850 | T3: =salarydata[[#This Row],[Basic Salary]]*tax -> 9250 | U3: =salarydata[[#This Row],[Basic Salary]]*healthinsurancepremium -> 3700 | V3: =salarydata[[#This Row],[Basic Salary]]*retirementplan -> 3700 | W3: =salarydata[[#This Row],[- Loan(1%)]]+salarydata[[#This Row],[- Tax(5%)]]+salarydata[[#This Row],[ - Health Insurance Premium(2%)]]+salarydata[[#This Row],[ - Retirement Plan(2%)]] -> 18500 | X3: =salarydata[[#This Row],[- Gross Salary]]-salarydata[[#This Row],[-Total DEDUCTION.]] -> 212750 | Y3: =DATEDIF(salarydata[[#This Row],[Hire Date]], TODAY(), "Y") -> 4 | AB3: - House Allowance (15%) | AC3: 0.15
A4: MDT016 | B4: Favour | C4: Daniel | D4: Cleaning | E4: Female | F4: 36 | G4: Delta | H4: 43690 | I4: 8000000016 | J4: 190000 | K4: 16 | L4: Fidelity Bank | M4: =salarydata[[#This Row],[Basic Salary]]*$AC$13 -> 1900 | N4: =salarydata[[#This Row],[Basic Salary]]*$AC$14 -> 28500 | O4: =salarydata[[#This Row],[Basic Salary]]*$AC$15 -> 9500 | P4: =salarydata[[#This Row],[Basic Salary]]*$AC$16 -> 3800 | Q4: =salarydata[[#This Row],[Basic Salary]]*$AC$17 -> 3800 | R4: =salarydata[[#This Row],[Basic Salary]]+salarydata[[#This Row],[ -Performance Bonus (1%)]]+salarydata[[#This Row],[- House Allowance (15%)]]+salarydata[[#This Row],[- Transport Allowance (5%)]]+salarydata[[#This Row],[- wordrope Allowance (2%)]]+salarydata[[#This Row],[- Over Time(2%)]] -> 237500 | S4: =salarydata[[#This Row],[Basic Salary]]*$AC$19 -> 1900 | T4: =salarydata[[#This Row],[Basic Salary]]*tax -> 9500 | U4: =salarydata[[#This Row],[Basic Salary]]*healthinsurancepremium -> 3800 | V4: =salarydata[[#This Row],[Basic Salary]]*retirementplan -> 3800 | W4: =salarydata[[#This Row],[- Loan(1%)]]+salarydata[[#This Row],[- Tax(5%)]]+salarydata[[#This Row],[ - Health Insurance Premium(2%)]]+salarydata[[#This Row],[ - Retirement Plan(2%)]] -> 19000 | X4: =salarydata[[#This Row],[- Gross Salary]]-salarydata[[#This Row],[-Total DEDUCTION.]] -> 218500 | Y4: =DATEDIF(salarydata[[#This Row],[Hire Date]], TODAY(), "Y") -> 7 | AB4: - Transport Allowance (5%) | AC4: 0.05
A5: MDT048 | B5: Susan | C5: Daniel | D5: Cleaning | E5: Female | F5: 34 | G5: Delta | H5: 44354 | I5: 8000000048 | J5: 195000 | K5: 48 | L5: Fidelity Bank | M5: =salarydata[[#This Row],[Basic Salary]]*$AC$13 -> 1950 | N5: =salarydata[[#This Row],[Basic Salary]]*$AC$14 -> 29250 | O5: =salarydata[[#This Row],[Basic Salary]]*$AC$15 -> 9750 | P5: =salarydata[[#This Row],[Basic Salary]]*$AC$16 -> 3900 | Q5: =salarydata[[#This Row],[Basic Salary]]*$AC$17 -> 3900 | R5: =salarydata[[#This Row],[Basic Salary]]+salarydata[[#This Row],[ -Performance Bonus (1%)]]+salarydata[[#This Row],[- House Allowance (15%)]]+salarydata[[#This Row],[- Transport Allowance (5%)]]+salarydata[[#This Row],[- wordrope Allowance (2%)]]+salarydata[[#This Row],[- Over Time(2%)]] -> 243750 | S5: =salarydata[[#This Row],[Basic Salary]]*$AC$19 -> 1950 | T5: =salarydata[[#This Row],[Basic Salary]]*tax -> 9750 | U5: =salarydata[[#This Row],[Basic Salary]]*healthinsurancepremium -> 3900 | V5: =salarydata[[#This Row],[Basic Salary]]*retirementplan -> 3900 | W5: =salarydata[[#This Row],[- Loan(1%)]]+salarydata[[#This Row],[- Tax(5%)]]+salarydata[[#This Row],[ - Health Insurance Premium(2%)]]+salarydata[[#This Row],[ - Retirement Plan(2%)]] -> 19500 | X5: =salarydata[[#This Row],[- Gross Salary]]-salarydata[[#This Row],[-Total DEDUCTION.]] -> 224250 | Y5: =DATEDIF(salarydata[[#This Row],[Hire Date]], TODAY(), "Y") -> 5 | AB5: - wordrope Allowance (2%) | AC5: 0.02
A6: MDT024 | B6: Comfort | C6: Essien | D6: Cleaning | E6: Female | F6: 44 | G6: Akwa Ibom | H6: 42423 | I6: 8000000024 | J6: 200000 | K6: 24 | L6: Access Bank | M6: =salarydata[[#This Row],[Basic Salary]]*$AC$13 -> 2000 | N6: =salarydata[[#This Row],[Basic Salary]]*$AC$14 -> 30000 | O6: =salarydata[[#This Row],[Basic Salary]]*$AC$15 -> 10000 | P6: =salarydata[[#This Row],[Basic Salary]]*$AC$16 -> 4000 | Q6: =salarydata[[#This Row],[Basic Salary]]*$AC$17 -> 4000 | R6: =salarydata[[#This Row],[Basic Salary]]+salarydata[[#This Row],[ -Performance Bonus (1%)]]+salarydata[[#This Row],[- House Allowance (15%)]]+salarydata[[#This Row],[- Transport Allowance (5%)]]+salarydata[[#This Row],[- wordrope Allowance (2%)]]+salarydata[[#This Row],[- Over Time(2%)]] -> 250000 | S6: =salarydata[[#This Row],[Basic Salary]]*$AC$19 -> 2000 | T6: =salarydata[[#This Row],[Basic Salary]]*tax -> 10000 | U6: =salarydata[[#This Row],[Basic Salary]]*healthinsurancepremium -> 4000 | V6: =salarydata[[#This Row],[Basic Salary]]*retirementplan -> 4000 | W6: =salarydata[[#This Row],[- Loan(1%)]]+salarydata[[#This Row],[- Tax(5%)]]+salarydata[[#This Row],[ - Health Insurance Premium(2%)]]+salarydata[[#This Row],[ - Retirement Plan(2%)]] -> 20000 | X6: =salarydata[[#This Row],[- Gross Salary]]-salarydata[[#This Row],[-Total DEDUCTION.]] -> 230000 | Y6: =DATEDIF(salarydata[[#This Row],[Hire Date]], TODAY(), "Y") -> 10 | AB6: - Over Time(2%) | AC6: 0.02
A7: MDT040 | B7: Angela | C7: Okeke | D7: Cleaning | E7: Female | F7: 42 | G7: Anambra | H7: 43449 | I7: 8000000040 | J7: 210000 | K7: 40 | L7: Access Bank | M7: =salarydata[[#This Row],[Basic Salary]]*$AC$13 -> 2100 | N7: =salarydata[[#This Row],[Basic Salary]]*$AC$14 -> 31500 | O7: =salarydata[[#This Row],[Basic Salary]]*$AC$15 -> 10500 | P7: =salarydata[[#This Row],[Basic Salary]]*$AC$16 -> 4200 | Q7: =salarydata[[#This Row],[Basic Salary]]*$AC$17 -> 4200 | R7: =salarydata[[#This Row],[Basic Salary]]+salarydata[[#This Row],[ -Performance Bonus (1%)]]+salarydata[[#This Row],[- House Allowance (15%)]]+salarydata[[#This Row],[- Transport Allowance (5%)]]+salarydata[[#This Row],[- wordrope Allowance (2%)]]+salarydata[[#This Row],[- Over Time(2%)]] -> 262500 | S7: =salarydata[[#This Row],[Basic Salary]]*$AC$19 -> 2100 | T7: =salarydata[[#This Row],[Basic Salary]]*tax -> 10500 | U7: =salarydata[[#This Row],[Basic Salary]]*healthinsurancepremium -> 4200 | V7: =salarydata[[#This Row],[Basic Salary]]*retirementplan -> 4200 | W7: =salarydata[[#This Row],[- Loan(1%)]]+salarydata[[#This Row],[- Tax(5%)]]+salarydata[[#This Row],[ - Health Insurance Premium(2%)]]+salarydata[[#This Row],[ - Retirement Plan(2%)]] -> 21000 | X7: =salarydata[[#This Row],[- Gross Salary]]-salarydata[[#This Row],[-Total DEDUCTION.]] -> 241500 | Y7: =DATEDIF(salarydata[[#This Row],[Hire Date]], TODAY(), "Y") -> 7 | AB7: - Gross Salary
A8: MDT006 | B8: Blessing | C8: Eze | D8: Customer Service | E8: Female | F8: 26 | G8: Imo | H8: 45353 | I8: 8000000006 | J8: 250000 | K8: 6 | L8: Fidelity Bank | M8: =salarydata[[#This Row],[Basic Salary]]*$AC$13 -> 2500 | N8: =salarydata[[#This Row],[Basic Salary]]*$AC$14 -> 37500 | O8: =salarydata[[#This Row],[Basic Salary]]*$AC$15 -> 12500 | P8: =salarydata[[#This Row],[Basic Salary]]*$AC$16 -> 5000 | Q8: =salarydata[[#This Row],[Basic Salary]]*$AC$17 -> 5000 | R8: =salarydata[[#This Row],[Basic Salary]]+salarydata[[#This Row],[ -Performance Bonus (1%)]]+salarydata[[#This Row],[- House Allowance (15%)]]+salarydata[[#This Row],[- Transport Allowance (5%)]]+salarydata[[#This Row],[- wordrope Allowance (2%)]]+salarydata[[#This Row],[- Over Time(2%)]] -> 312500 | S8: =salarydata[[#This Row],[Basic Salary]]*$AC$19 -> 2500 | T8: =salarydata[[#This Row],[Basic Salary]]*tax -> 12500 | U8: =salarydata[[#This Row],[Basic Salary]]*healthinsurancepremium -> 5000 | V8: =salarydata[[#This Row],[Basic Salary]]*retirementplan -> 5000 | W8: =salarydata[[#This Row],[- Loan(1%)]]+salarydata[[#This Row],[- Tax(5%)]]+salarydata[[#This Row],[ - Health Insurance Premium(2%)]]+salarydata[[#This Row],[ - Retirement Plan(2%)]] -> 25000 | X8: =salarydata[[#This Row],[- Gross Salary]]-salarydata[[#This Row],[-Total DEDUCTION.]] -> 287500 | Y8: =DATEDIF(salarydata[[#This Row],[Hire Date]], TODAY(), "Y") -> 2 | AB8: - Loan(1%) | AC8: 0.01
A9: MDT029 | B9: Gabriel | C9: Sunday | D9: Customer Service | E9: Male | F9: 26 | G9: Edo | H9: 45459 | I9: 8000000029 | J9: 260000 | K9: 29 | L9: Access Bank | M9: =salarydata[[#This Row],[Basic Salary]]*$AC$13 -> 2600 | N9: =salarydata[[#This Row],[Basic Salary]]*$AC$14 -> 39000 | O9: =salarydata[[#This Row],[Basic Salary]]*$AC$15 -> 13000 | P9: =salarydata[[#This Row],[Basic Salary]]*$AC$16 -> 5200 | Q9: =salarydata[[#This Row],[Basic Salary]]*$AC$17 -> 5200 | R9: =salarydata[[#This Row],[Basic Salary]]+salarydata[[#This Row],[ -Performance Bonus (1%)]]+salarydata[[#This Row],[- House Allowance (15%)]]+salarydata[[#This Row],[- Transport Allowance (5%)]]+salarydata[[#This Row],[- wordrope Allowance (2%)]]+salarydata[[#This Row],[- Over Time(2%)]] -> 325000 | S9: =salarydata[[#This Row],[Basic Salary]]*$AC$19 -> 2600 | T9: =salarydata[[#This Row],[Basic Salary]]*tax -> 13000 | U9: =salarydata[[#This Row],[Basic Salary]]*healthinsurancepremium -> 5200 | V9: =salarydata[[#This Row],[Basic Salary]]*retirementplan -> 5200 | W9: =salarydata[[#This Row],[- Loan(1%)]]+salarydata[[#This Row],[- Tax(5%)]]+salarydata[[#This Row],[ - Health Insurance Premium(2%)]]+salarydata[[#This Row],[ - Retirement Plan(2%)]] -> 26000 | X9: =salarydata[[#This Row],[- Gross Salary]]-salarydata[[#This Row],[-Total DEDUCTION.]] -> 299000 | Y9: =DATEDIF(salarydata[[#This Row],[Hire Date]], TODAY(), "Y") -> 2 | AB9: - Tax(5%) | AC9: 0.05
A10: MDT013 | B10: Victor | C10: Chukwu | D10: Customer Service | E10: Male | F10: 32 | G10: Enugu | H10: 44503 | I10: 8000000013 | J10: 270000 | K10: 13 | L10: Access Bank | M10: =salarydata[[#This Row],[Basic Salary]]*$AC$13 -> 2700 | N10: =salarydata[[#This Row],[Basic Salary]]*$AC$14 -> 40500 | O10: =salarydata[[#This Row],[Basic Salary]]*$AC$15 -> 13500 | P10: =salarydata[[#This Row],[Basic Salary]]*$AC$16 -> 5400 | Q10: =salarydata[[#This Row],[Basic Salary]]*$AC$17 -> 5400 | R10: =salarydata[[#This Row],[Basic Salary]]+salarydata[[#This Row],[ -Performance Bonus (1%)]]+salarydata[[#This Row],[- House Allowance (15%)]]+salarydata[[#This Row],[- Transport Allowance (5%)]]+salarydata[[#This Row],[- wordrope Allowance (2%)]]+salarydata[[#This Row],[- Over Time(2%)]] -> 337500 | S10: =salarydata[[#This Row],[Basic Salary]]*$AC$19 -> 2700 | T10: =salarydata[[#This Row],[Basic Salary]]*tax -> 13500 | U10: =salarydata[[#This Row],[Basic Salary]]*healthinsurancepremium -> 5400 | V10: =salarydata[[#This Row],[Basic Salary]]*retirementplan -> 5400 | W10: =salarydata[[#This Row],[- Loan(1%)]]+salarydata[[#This Row],[- Tax(5%)]]+salarydata[[#This Row],[ - Health Insurance Premium(2%)]]+salarydata[[#This Row],[ - Retirement Plan(2%)]] -> 27000 | X10: =salarydata[[#This Row],[- Gross Salary]]-salarydata[[#This Row],[-Total DEDUCTION.]] -> 310500 | Y10: =DATEDIF(salarydata[[#This Row],[Hire Date]], TODAY(), "Y") -> 4
A11: MDT003 | B11: Michael | C11: Ibrahim | D11: Security | E11: Male | F11: 41 | G11: Kaduna | H11: 43122 | I11: 8000000003 | J11: 280000 | K11: 3 | L11: First Bank | M11: =salarydata[[#This Row],[Basic Salary]]*$AC$13 -> 2800 | N11: =salarydata[[#This Row],[Basic Salary]]*$AC$14 -> 42000 | O11: =salarydata[[#This Row],[Basic Salary]]*$AC$15 -> 14000 | P11: =salarydata[[#This Row],[Basic Salary]]*$AC$16 -> 5600 | Q11: =salarydata[[#This Row],[Basic Salary]]*$AC$17 -> 5600 | R11: =salarydata[[#This Row],[Basic Salary]]+salarydata[[#This Row],[ -Performance Bonus (1%)]]+salarydata[[#This Row],[- House Allowance (15%)]]+salarydata[[#This Row],[- Transport Allowance (5%)]]+salarydata[[#This Row],[- wordrope Allowance (2%)]]+salarydata[[#This Row],[- Over Time(2%)]] -> 350000 | S11: =salarydata[[#This Row],[Basic Salary]]*$AC$19 -> 2800 | T11: =salarydata[[#This Row],[Basic Salary]]*tax -> 14000 | U11: =salarydata[[#This Row],[Basic Salary]]*healthinsurancepremium -> 5600 | V11: =salarydata[[#This Row],[Basic Salary]]*retirementplan -> 5600 | W11: =salarydata[[#This Row],[- Loan(1%)]]+salarydata[[#This Row],[- Tax(5%)]]+salarydata[[#This Row],[ - Health Insurance Premium(2%)]]+salarydata[[#This Row],[ - Retirement Plan(2%)]] -> 28000 | X11: =salarydata[[#This Row],[- Gross Salary]]-salarydata[[#This Row],[-Total DEDUCTION.]] -> 322000 | Y11: =DATEDIF(salarydata[[#This Row],[Hire Date]], TODAY(), "Y") -> 8
A12: MDT021 | B12: Francis | C12: Okeke | D12: Customer Service | E12: Male | F12: 31 | G12: Anambra | H12: 44484 | I12: 8000000021 | J12: 285000 | K12: 21 | L12: First Bank | M12: =salarydata[[#This Row],[Basic Salary]]*$AC$13 -> 2850 | N12: =salarydata[[#This Row],[Basic Salary]]*$AC$14 -> 42750 | O12: =salarydata[[#This Row],[Basic Salary]]*$AC$15 -> 14250 | P12: =salarydata[[#This Row],[Basic Salary]]*$AC$16 -> 5700 | Q12: =salarydata[[#This Row],[Basic Salary]]*$AC$17 -> 5700 | R12: =salarydata[[#This Row],[Basic Salary]]+salarydata[[#This Row],[ -Performance Bonus (1%)]]+salarydata[[#This Row],[- House Allowance (15%)]]+salarydata[[#This Row],[- Transport Allowance (5%)]]+salarydata[[#This Row],[- wordrope Allowance (2%)]]+salarydata[[#This Row],[- Over Time(2%)]] -> 356250 | S12: =salarydata[[#This Row],[Basic Salary]]*$AC$19 -> 2850 | T12: =salarydata[[#This Row],[Basic Salary]]*tax -> 14250 | U12: =salarydata[[#This Row],[Basic Salary]]*healthinsurancepremium -> 5700 | V12: =salarydata[[#This Row],[Basic Salary]]*retirementplan -> 5700 | W12: =salarydata[[#This Row],[- Loan(1%)]]+salarydata[[#This Row],[- Tax(5%)]]+salarydata[[#This Row],[ - Health Insurance Premium(2%)]]+salarydata[[#This Row],[ - Retirement Plan(2%)]] -> 28500 | X12: =salarydata[[#This Row],[- Gross Salary]]-salarydata[[#This Row],[-Total DEDUCTION.]] -> 327750 | Y12: =DATEDIF(salarydata[[#This Row],[Hire Date]], TODAY(), "Y") -> 4
A13: MDT023 | B13: Isaac | C13: Lawal | D13: Security | E13: Male | F13: 40 | G13: Kwara | H13: 43441 | I13: 8000000023 | J13: 290000 | K13: 23 | L13: GTBank | M13: =salarydata[[#This Row],[Basic Salary]]*$AC$13 -> 2900 | N13: =salarydata[[#This Row],[Basic Salary]]*$AC$14 -> 43500 | O13: =salarydata[[#This Row],[Basic Salary]]*$AC$15 -> 14500 | P13: =salarydata[[#This Row],[Basic Salary]]*$AC$16 -> 5800 | Q13: =salarydata[[#This Row],[Basic Salary]]*$AC$17 -> 5800 | R13: =salarydata[[#This Row],[Basic Salary]]+salarydata[[#This Row],[ -Performance Bonus (1%)]]+salarydata[[#This Row],[- House Allowance (15%)]]+salarydata[[#This Row],[- Transport Allowance (5%)]]+salarydata[[#This Row],[- wordrope Allowance (2%)]]+salarydata[[#This Row],[- Over Time(2%)]] -> 362500 | S13: =salarydata[[#This Row],[Basic Salary]]*$AC$19 -> 2900 | T13: =salarydata[[#This Row],[Basic Salary]]*tax -> 14500 | U13: =salarydata[[#This Row],[Basic Salary]]*healthinsurancepremium -> 5800 | V13: =salarydata[[#This Row],[Basic Salary]]*retirementplan -> 5800 | W13: =salarydata[[#This Row],[- Loan(1%)]]+salarydata[[#This Row],[- Tax(5%)]]+salarydata[[#This Row],[ - Health Insurance Premium(2%)]]+salarydata[[#This Row],[ - Retirement Plan(2%)]] -> 29000 | X13: =salarydata[[#This Row],[- Gross Salary]]-salarydata[[#This Row],[-Total DEDUCTION.]] -> 333500 | Y13: =DATEDIF(salarydata[[#This Row],[Hire Date]], TODAY(), "Y") -> 7 | AB13: -Performance Bonus (1%) | AC13: 0.01
A14: MDT037 | B14: Richard | C14: Eze | D14: Customer Service | E14: Male | F14: 34 | G14: Abia | H14: 44110 | I14: 8000000037 | J14: 295000 | K14: 37 | L14: UBA | M14: =salarydata[[#This Row],[Basic Salary]]*$AC$13 -> 2950 | N14: =salarydata[[#This Row],[Basic Salary]]*$AC$14 -> 44250 | O14: =salarydata[[#This Row],[Basic Salary]]*$AC$15 -> 14750 | P14: =salarydata[[#This Row],[Basic Salary]]*$AC$16 -> 5900 | Q14: =salarydata[[#This Row],[Basic Salary]]*$AC$17 -> 5900 | R14: =salarydata[[#This Row],[Basic Salary]]+salarydata[[#This Row],[ -Performance Bonus (1%)]]+salarydata[[#This Row],[- House Allowance (15%)]]+salarydata[[#This Row],[- Transport Allowance (5%)]]+salarydata[[#This Row],[- wordrope Allowance (2%)]]+salarydata[[#This Row],[- Over Time(2%)]] -> 368750 | S14: =salarydata[[#This Row],[Basic Salary]]*$AC$19 -> 2950 | T14: =salarydata[[#This Row],[Basic Salary]]*tax -> 14750 | U14: =salarydata[[#This Row],[Basic Salary]]*healthinsurancepremium -> 5900 | V14: =salarydata[[#This Row],[Basic Salary]]*retirementplan -> 5900 | W14: =salarydata[[#This Row],[- Loan(1%)]]+salarydata[[#This Row],[- Tax(5%)]]+salarydata[[#This Row],[ - Health Insurance Premium(2%)]]+salarydata[[#This Row],[ - Retirement Plan(2%)]] -> 29500 | X14: =salarydata[[#This Row],[- Gross Salary]]-salarydata[[#This Row],[-Total DEDUCTION.]] -> 339250 | Y14: =DATEDIF(salarydata[[#This Row],[Hire Date]], TODAY(), "Y") -> 5 | AB14: - House Allowance (15%) | AC14: 0.15
A15: MDT005 | B15: Samuel | C15: Okoro | D15: Sales | E15: Male | F15: 27 | G15: Enugu | H15: 45244 | I15: 8000000005 | J15: 300000 | K15: 5 | L15: Zenith Bank | M15: =salarydata[[#This Row],[Basic Salary]]*$AC$13 -> 3000 | N15: =salarydata[[#This Row],[Basic Salary]]*$AC$14 -> 45000 | O15: =salarydata[[#This Row],[Basic Salary]]*$AC$15 -> 15000 | P15: =salarydata[[#This Row],[Basic Salary]]*$AC$16 -> 6000 | Q15: =salarydata[[#This Row],[Basic Salary]]*$AC$17 -> 6000 | R15: =salarydata[[#This Row],[Basic Salary]]+salarydata[[#This Row],[ -Performance Bonus (1%)]]+salarydata[[#This Row],[- House Allowance (15%)]]+salarydata[[#This Row],[- Transport Allowance (5%)]]+salarydata[[#This Row],[- wordrope Allowance (2%)]]+salarydata[[#This Row],[- Over Time(2%)]] -> 375000 | S15: =salarydata[[#This Row],[Basic Salary]]*$AC$19 -> 3000 | T15: =salarydata[[#This Row],[Basic Salary]]*tax -> 15000 | U15: =salarydata[[#This Row],[Basic Salary]]*healthinsurancepremium -> 6000 | V15: =salarydata[[#This Row],[Basic Salary]]*retirementplan -> 6000 | W15: =salarydata[[#This Row],[- Loan(1%)]]+salarydata[[#This Row],[- Tax(5%)]]+salarydata[[#This Row],[ - Health Insurance Premium(2%)]]+salarydata[[#This Row],[ - Retirement Plan(2%)]] -> 30000 | X15: =salarydata[[#This Row],[- Gross Salary]]-salarydata[[#This Row],[-Total DEDUCTION.]] -> 345000 | Y15: =DATEDIF(salarydata[[#This Row],[Hire Date]], TODAY(), "Y") -> 2 | AB15: - Transport Allowance (5%) | AC15: 0.05
A16: MDT015 | B16: Emmanuel | C16: Obi | D16: Security | E16: Male | F16: 45 | G16: Imo | H16: 42174 | I16: 8000000015 | J16: 300000 | K16: 15 | L16: UBA | M16: =salarydata[[#This Row],[Basic Salary]]*$AC$13 -> 3000 | N16: =salarydata[[#This Row],[Basic Salary]]*$AC$14 -> 45000 | O16: =salarydata[[#This Row],[Basic Salary]]*$AC$15 -> 15000 | P16: =salarydata[[#This Row],[Basic Salary]]*$AC$16 -> 6000 | Q16: =salarydata[[#This Row],[Basic Salary]]*$AC$17 -> 6000 | R16: =salarydata[[#This Row],[Basic Salary]]+salarydata[[#This Row],[ -Performance Bonus (1%)]]+salarydata[[#This Row],[- House Allowance (15%)]]+salarydata[[#This Row],[- Transport Allowance (5%)]]+salarydata[[#This Row],[- wordrope Allowance (2%)]]+salarydata[[#This Row],[- Over Time(2%)]] -> 375000 | S16: =salarydata[[#This Row],[Basic Salary]]*$AC$19 -> 3000 | T16: =salarydata[[#This Row],[Basic Salary]]*tax -> 15000 | U16: =salarydata[[#This Row],[Basic Salary]]*healthinsurancepremium -> 6000 | V16: =salarydata[[#This Row],[Basic Salary]]*retirementplan -> 6000 | W16: =salarydata[[#This Row],[- Loan(1%)]]+salarydata[[#This Row],[- Tax(5%)]]+salarydata[[#This Row],[ - Health Insurance Premium(2%)]]+salarydata[[#This Row],[ - Retirement Plan(2%)]] -> 30000 | X16: =salarydata[[#This Row],[- Gross Salary]]-salarydata[[#This Row],[-Total DEDUCTION.]] -> 345000 | Y16: =DATEDIF(salarydata[[#This Row],[Hire Date]], TODAY(), "Y") -> 11 | AB16: - wordrope Allowance (2%) | AC16: 0.02
A17: MDT031 | B17: Stephen | C17: Okafor | D17: Security | E17: Male | F17: 39 | G17: Enugu | H17: 44137 | I17: 8000000031 | J17: 305000 | K17: 31 | L17: UBA | M17: =salarydata[[#This Row],[Basic Salary]]*$AC$13 -> 3050 | N17: =salarydata[[#This Row],[Basic Salary]]*$AC$14 -> 45750 | O17: =salarydata[[#This Row],[Basic Salary]]*$AC$15 -> 15250 | P17: =salarydata[[#This Row],[Basic Salary]]*$AC$16 -> 6100 | Q17: =salarydata[[#This Row],[Basic Salary]]*$AC$17 -> 6100 | R17: =salarydata[[#This Row],[Basic Salary]]+salarydata[[#This Row],[ -Performance Bonus (1%)]]+salarydata[[#This Row],[- House Allowance (15%)]]+salarydata[[#This Row],[- Transport Allowance (5%)]]+salarydata[[#This Row],[- wordrope Allowance (2%)]]+salarydata[[#This Row],[- Over Time(2%)]] -> 381250 | S17: =salarydata[[#This Row],[Basic Salary]]*$AC$19 -> 3050 | T17: =salarydata[[#This Row],[Basic Salary]]*tax -> 15250 | U17: =salarydata[[#This Row],[Basic Salary]]*healthinsurancepremium -> 6100 | V17: =salarydata[[#This Row],[Basic Salary]]*retirementplan -> 6100 | W17: =salarydata[[#This Row],[- Loan(1%)]]+salarydata[[#This Row],[- Tax(5%)]]+salarydata[[#This Row],[ - Health Insurance Premium(2%)]]+salarydata[[#This Row],[ - Retirement Plan(2%)]] -> 30500 | X17: =salarydata[[#This Row],[- Gross Salary]]-salarydata[[#This Row],[-Total DEDUCTION.]] -> 350750 | Y17: =DATEDIF(salarydata[[#This Row],[Hire Date]], TODAY(), "Y") -> 5 | AB17: - Over Time(2%) | AC17: 0.02
A18: MDT045 | B18: Lawrence | C18: Ibrahim | D18: Customer Service | E18: Male | F18: 38 | G18: Kaduna | H18: 43512 | I18: 8000000045 | J18: 305000 | K18: 45 | L18: Access Bank | M18: =salarydata[[#This Row],[Basic Salary]]*$AC$13 -> 3050 | N18: =salarydata[[#This Row],[Basic Salary]]*$AC$14 -> 45750 | O18: =salarydata[[#This Row],[Basic Salary]]*$AC$15 -> 15250 | P18: =salarydata[[#This Row],[Basic Salary]]*$AC$16 -> 6100 | Q18: =salarydata[[#This Row],[Basic Salary]]*$AC$17 -> 6100 | R18: =salarydata[[#This Row],[Basic Salary]]+salarydata[[#This Row],[ -Performance Bonus (1%)]]+salarydata[[#This Row],[- House Allowance (15%)]]+salarydata[[#This Row],[- Transport Allowance (5%)]]+salarydata[[#This Row],[- wordrope Allowance (2%)]]+salarydata[[#This Row],[- Over Time(2%)]] -> 381250 | S18: =salarydata[[#This Row],[Basic Salary]]*$AC$19 -> 3050 | T18: =salarydata[[#This Row],[Basic Salary]]*tax -> 15250 | U18: =salarydata[[#This Row],[Basic Salary]]*healthinsurancepremium -> 6100 | V18: =salarydata[[#This Row],[Basic Salary]]*retirementplan -> 6100 | W18: =salarydata[[#This Row],[- Loan(1%)]]+salarydata[[#This Row],[- Tax(5%)]]+salarydata[[#This Row],[ - Health Insurance Premium(2%)]]+salarydata[[#This Row],[ - Retirement Plan(2%)]] -> 30500 | X18: =salarydata[[#This Row],[- Gross Salary]]-salarydata[[#This Row],[-Total DEDUCTION.]] -> 350750 | Y18: =DATEDIF(salarydata[[#This Row],[Hire Date]], TODAY(), "Y") -> 7 | AB18: - Gross Salary
A19: MDT012 | B19: Janet | C19: Williams | D19: Sales | E19: Female | F19: 28 | G19: Rivers | H19: 44854 | I19: 8000000012 | J19: 310000 | K19: 12 | L19: GTBank | M19: =salarydata[[#This Row],[Basic Salary]]*$AC$13 -> 3100 | N19: =salarydata[[#This Row],[Basic Salary]]*$AC$14 -> 46500 | O19: =salarydata[[#This Row],[Basic Salary]]*$AC$15 -> 15500 | P19: =salarydata[[#This Row],[Basic Salary]]*$AC$16 -> 6200 | Q19: =salarydata[[#This Row],[Basic Salary]]*$AC$17 -> 6200 | R19: =salarydata[[#This Row],[Basic Salary]]+salarydata[[#This Row],[ -Performance Bonus (1%)]]+salarydata[[#This Row],[- House Allowance (15%)]]+salarydata[[#This Row],[- Transport Allowance (5%)]]+salarydata[[#This Row],[- wordrope Allowance (2%)]]+salarydata[[#This Row],[- Over Time(2%)]] -> 387500 | S19: =salarydata[[#This Row],[Basic Salary]]*$AC$19 -> 3100 | T19: =salarydata[[#This Row],[Basic Salary]]*tax -> 15500 | U19: =salarydata[[#This Row],[Basic Salary]]*healthinsurancepremium -> 6200 | V19: =salarydata[[#This Row],[Basic Salary]]*retirementplan -> 6200 | W19: =salarydata[[#This Row],[- Loan(1%)]]+salarydata[[#This Row],[- Tax(5%)]]+salarydata[[#This Row],[ - Health Insurance Premium(2%)]]+salarydata[[#This Row],[ - Retirement Plan(2%)]] -> 31000 | X19: =salarydata[[#This Row],[- Gross Salary]]-salarydata[[#This Row],[-Total DEDUCTION.]] -> 356500 | Y19: =DATEDIF(salarydata[[#This Row],[Hire Date]], TODAY(), "Y") -> 3 | AB19: - Loan(1%) | AC19: 0.01
A20: MDT022 | B20: Linda | C20: Ibrahim | D20: Marketing | E20: Female | F20: 27 | G20: Kano | H20: 45446 | I20: 8000000022 | J20: 310000 | K20: 22 | L20: Zenith Bank | M20: =salarydata[[#This Row],[Basic Salary]]*$AC$13 -> 3100 | N20: =salarydata[[#This Row],[Basic Salary]]*$AC$14 -> 46500 | O20: =salarydata[[#This Row],[Basic Salary]]*$AC$15 -> 15500 | P20: =salarydata[[#This Row],[Basic Salary]]*$AC$16 -> 6200 | Q20: =salarydata[[#This Row],[Basic Salary]]*$AC$17 -> 6200 | R20: =salarydata[[#This Row],[Basic Salary]]+salarydata[[#This Row],[ -Performance Bonus (1%)]]+salarydata[[#This Row],[- House Allowance (15%)]]+salarydata[[#This Row],[- Transport Allowance (5%)]]+salarydata[[#This Row],[- wordrope Allowance (2%)]]+salarydata[[#This Row],[- Over Time(2%)]] -> 387500 | S20: =salarydata[[#This Row],[Basic Salary]]*$AC$19 -> 3100 | T20: =salarydata[[#This Row],[Basic Salary]]*tax -> 15500 | U20: =salarydata[[#This Row],[Basic Salary]]*healthinsurancepremium -> 6200 | V20: =salarydata[[#This Row],[Basic Salary]]*retirementplan -> 6200 | W20: =salarydata[[#This Row],[- Loan(1%)]]+salarydata[[#This Row],[- Tax(5%)]]+salarydata[[#This Row],[ - Health Insurance Premium(2%)]]+salarydata[[#This Row],[ - Retirement Plan(2%)]] -> 31000 | X20: =salarydata[[#This Row],[- Gross Salary]]-salarydata[[#This Row],[-Total DEDUCTION.]] -> 356500 | Y20: =DATEDIF(salarydata[[#This Row],[Hire Date]], TODAY(), "Y") -> 2 | AB20: - Tax(5%) | AC20: 0.05
A21: MDT028 | B21: Sharon | C21: James | D21: Sales | E21: Female | F21: 32 | G21: Lagos | H21: 44440 | I21: 8000000028 | J21: 315000 | K21: 28 | L21: GTBank | M21: =salarydata[[#This Row],[Basic Salary]]*$AC$13 -> 3150 | N21: =salarydata[[#This Row],[Basic Salary]]*$AC$14 -> 47250 | O21: =salarydata[[#This Row],[Basic Salary]]*$AC$15 -> 15750 | P21: =salarydata[[#This Row],[Basic Salary]]*$AC$16 -> 6300 | Q21: =salarydata[[#This Row],[Basic Salary]]*$AC$17 -> 6300 | R21: =salarydata[[#This Row],[Basic Salary]]+salarydata[[#This Row],[ -Performance Bonus (1%)]]+salarydata[[#This Row],[- House Allowance (15%)]]+salarydata[[#This Row],[- Transport Allowance (5%)]]+salarydata[[#This Row],[- wordrope Allowance (2%)]]+salarydata[[#This Row],[- Over Time(2%)]] -> 393750 | S21: =salarydata[[#This Row],[Basic Salary]]*$AC$19 -> 3150 | T21: =salarydata[[#This Row],[Basic Salary]]*tax -> 15750 | U21: =salarydata[[#This Row],[Basic Salary]]*healthinsurancepremium -> 6300 | V21: =salarydata[[#This Row],[Basic Salary]]*retirementplan -> 6300 | W21: =salarydata[[#This Row],[- Loan(1%)]]+salarydata[[#This Row],[- Tax(5%)]]+salarydata[[#This Row],[ - Health Insurance Premium(2%)]]+salarydata[[#This Row],[ - Retirement Plan(2%)]] -> 31500 | X21: =salarydata[[#This Row],[- Gross Salary]]-salarydata[[#This Row],[-Total DEDUCTION.]] -> 362250 | Y21: =DATEDIF(salarydata[[#This Row],[Hire Date]], TODAY(), "Y") -> 5
A22: MDT039 | B22: Matthew | C22: Johnson | D22: Security | E22: Male | F22: 46 | G22: Lagos | H22: 42189 | I22: 8000000039 | J22: 315000 | K22: 39 | L22: GTBank | M22: =salarydata[[#This Row],[Basic Salary]]*$AC$13 -> 3150 | N22: =salarydata[[#This Row],[Basic Salary]]*$AC$14 -> 47250 | O22: =salarydata[[#This Row],[Basic Salary]]*$AC$15 -> 15750 | P22: =salarydata[[#This Row],[Basic Salary]]*$AC$16 -> 6300 | Q22: =salarydata[[#This Row],[Basic Salary]]*$AC$17 -> 6300 | R22: =salarydata[[#This Row],[Basic Salary]]+salarydata[[#This Row],[ -Performance Bonus (1%)]]+salarydata[[#This Row],[- House Allowance (15%)]]+salarydata[[#This Row],[- Transport Allowance (5%)]]+salarydata[[#This Row],[- wordrope Allowance (2%)]]+salarydata[[#This Row],[- Over Time(2%)]] -> 393750 | S22: =salarydata[[#This Row],[Basic Salary]]*$AC$19 -> 3150 | T22: =salarydata[[#This Row],[Basic Salary]]*tax -> 15750 | U22: =salarydata[[#This Row],[Basic Salary]]*healthinsurancepremium -> 6300 | V22: =salarydata[[#This Row],[Basic Salary]]*retirementplan -> 6300 | W22: =salarydata[[#This Row],[- Loan(1%)]]+salarydata[[#This Row],[- Tax(5%)]]+salarydata[[#This Row],[ - Health Insurance Premium(2%)]]+salarydata[[#This Row],[ - Retirement Plan(2%)]] -> 31500 | X22: =salarydata[[#This Row],[- Gross Salary]]-salarydata[[#This Row],[-Total DEDUCTION.]] -> 362250 | Y22: =DATEDIF(salarydata[[#This Row],[Hire Date]], TODAY(), "Y") -> 11
A23: MDT002 | B23: Grace | C23: Okafor | D23: HR | E23: Female | F23: 34 | G23: Anambra | H23: 43746 | I23: 8000000002 | J23: 320000 | K23: 2 | L23: Access Bank | M23: =salarydata[[#This Row],[Basic Salary]]*$AC$13 -> 3200 | N23: =salarydata[[#This Row],[Basic Salary]]*$AC$14 -> 48000 | O23: =salarydata[[#This Row],[Basic Salary]]*$AC$15 -> 16000 | P23: =salarydata[[#This Row],[Basic Salary]]*$AC$16 -> 6400 | Q23: =salarydata[[#This Row],[Basic Salary]]*$AC$17 -> 6400 | R23: =salarydata[[#This Row],[Basic Salary]]+salarydata[[#This Row],[ -Performance Bonus (1%)]]+salarydata[[#This Row],[- House Allowance (15%)]]+salarydata[[#This Row],[- Transport Allowance (5%)]]+salarydata[[#This Row],[- wordrope Allowance (2%)]]+salarydata[[#This Row],[- Over Time(2%)]] -> 400000 | S23: =salarydata[[#This Row],[Basic Salary]]*$AC$19 -> 3200 | T23: =salarydata[[#This Row],[Basic Salary]]*tax -> 16000 | U23: =salarydata[[#This Row],[Basic Salary]]*healthinsurancepremium -> 6400 | V23: =salarydata[[#This Row],[Basic Salary]]*retirementplan -> 6400 | W23: =salarydata[[#This Row],[- Loan(1%)]]+salarydata[[#This Row],[- Tax(5%)]]+salarydata[[#This Row],[ - Health Insurance Premium(2%)]]+salarydata[[#This Row],[ - Retirement Plan(2%)]] -> 32000 | X23: =salarydata[[#This Row],[- Gross Salary]]-salarydata[[#This Row],[-Total DEDUCTION.]] -> 368000 | Y23: =DATEDIF(salarydata[[#This Row],[Hire Date]], TODAY(), "Y") -> 6
A24: MDT047 | B24: George | C24: Nwosu | D24: Security | E24: Male | F24: 43 | G24: Enugu | H24: 42807 | I24: 8000000047 | J24: 320000 | K24: 47 | L24: UBA | M24: =salarydata[[#This Row],[Basic Salary]]*$AC$13 -> 3200 | N24: =salarydata[[#This Row],[Basic Salary]]*$AC$14 -> 48000 | O24: =salarydata[[#This Row],[Basic Salary]]*$AC$15 -> 16000 | P24: =salarydata[[#This Row],[Basic Salary]]*$AC$16 -> 6400 | Q24: =salarydata[[#This Row],[Basic Salary]]*$AC$17 -> 6400 | R24: =salarydata[[#This Row],[Basic Salary]]+salarydata[[#This Row],[ -Performance Bonus (1%)]]+salarydata[[#This Row],[- House Allowance (15%)]]+salarydata[[#This Row],[- Transport Allowance (5%)]]+salarydata[[#This Row],[- wordrope Allowance (2%)]]+salarydata[[#This Row],[- Over Time(2%)]] -> 400000 | S24: =salarydata[[#This Row],[Basic Salary]]*$AC$19 -> 3200 | T24: =salarydata[[#This Row],[Basic Salary]]*tax -> 16000 | U24: =salarydata[[#This Row],[Basic Salary]]*healthinsurancepremium -> 6400 | V24: =salarydata[[#This Row],[Basic Salary]]*retirementplan -> 6400 | W24: =salarydata[[#This Row],[- Loan(1%)]]+salarydata[[#This Row],[- Tax(5%)]]+salarydata[[#This Row],[ - Health Insurance Premium(2%)]]+salarydata[[#This Row],[ - Retirement Plan(2%)]] -> 32000 | X24: =salarydata[[#This Row],[- Gross Salary]]-salarydata[[#This Row],[-Total DEDUCTION.]] -> 368000 | Y24: =DATEDIF(salarydata[[#This Row],[Hire Date]], TODAY(), "Y") -> 9
A25: MDT020 | B25: Helen | C25: Adeyemi | D25: Sales | E25: Female | F25: 33 | G25: Oyo | H25: 44079 | I25: 8000000020 | J25: 325000 | K25: 20 | L25: UBA | M25: =salarydata[[#This Row],[Basic Salary]]*$AC$13 -> 3250 | N25: =salarydata[[#This Row],[Basic Salary]]*$AC$14 -> 48750 | O25: =salarydata[[#This Row],[Basic Salary]]*$AC$15 -> 16250 | P25: =salarydata[[#This Row],[Basic Salary]]*$AC$16 -> 6500 | Q25: =salarydata[[#This Row],[Basic Salary]]*$AC$17 -> 6500 | R25: =salarydata[[#This Row],[Basic Salary]]+salarydata[[#This Row],[ -Performance Bonus (1%)]]+salarydata[[#This Row],[- House Allowance (15%)]]+salarydata[[#This Row],[- Transport Allowance (5%)]]+salarydata[[#This Row],[- wordrope Allowance (2%)]]+salarydata[[#This Row],[- Over Time(2%)]] -> 406250 | S25: =salarydata[[#This Row],[Basic Salary]]*$AC$19 -> 3250 | T25: =salarydata[[#This Row],[Basic Salary]]*tax -> 16250 | U25: =salarydata[[#This Row],[Basic Salary]]*healthinsurancepremium -> 6500 | V25: =salarydata[[#This Row],[Basic Salary]]*retirementplan -> 6500 | W25: =salarydata[[#This Row],[- Loan(1%)]]+salarydata[[#This Row],[- Tax(5%)]]+salarydata[[#This Row],[ - Health Insurance Premium(2%)]]+salarydata[[#This Row],[ - Retirement Plan(2%)]] -> 32500 | X25: =salarydata[[#This Row],[- Gross Salary]]-salarydata[[#This Row],[-Total DEDUCTION.]] -> 373750 | Y25: =DATEDIF(salarydata[[#This Row],[Hire Date]], TODAY(), "Y") -> 6
A26: MDT044 | B26: Jennifer | C26: Chukwu | D26: Sales | E26: Female | F26: 29 | G26: Imo | H26: 45144 | I26: 8000000044 | J26: 325000 | K26: 44 | L26: GTBank | M26: =salarydata[[#This Row],[Basic Salary]]*$AC$13 -> 3250 | N26: =salarydata[[#This Row],[Basic Salary]]*$AC$14 -> 48750 | O26: =salarydata[[#This Row],[Basic Salary]]*$AC$15 -> 16250 | P26: =salarydata[[#This Row],[Basic Salary]]*$AC$16 -> 6500 | Q26: =salarydata[[#This Row],[Basic Salary]]*$AC$17 -> 6500 | R26: =salarydata[[#This Row],[Basic Salary]]+salarydata[[#This Row],[ -Performance Bonus (1%)]]+salarydata[[#This Row],[- House Allowance (15%)]]+salarydata[[#This Row],[- Transport Allowance (5%)]]+salarydata[[#This Row],[- wordrope Allowance (2%)]]+salarydata[[#This Row],[- Over Time(2%)]] -> 406250 | S26: =salarydata[[#This Row],[Basic Salary]]*$AC$19 -> 3250 | T26: =salarydata[[#This Row],[Basic Salary]]*tax -> 16250 | U26: =salarydata[[#This Row],[Basic Salary]]*healthinsurancepremium -> 6500 | V26: =salarydata[[#This Row],[Basic Salary]]*retirementplan -> 6500 | W26: =salarydata[[#This Row],[- Loan(1%)]]+salarydata[[#This Row],[- Tax(5%)]]+salarydata[[#This Row],[ - Health Insurance Premium(2%)]]+salarydata[[#This Row],[ - Retirement Plan(2%)]] -> 32500 | X26: =salarydata[[#This Row],[- Gross Salary]]-salarydata[[#This Row],[-Total DEDUCTION.]] -> 373750 | Y26: =DATEDIF(salarydata[[#This Row],[Hire Date]], TODAY(), "Y") -> 3
A27: MDT014 | B27: Aisha | C27: Bello | D27: Marketing | E27: Female | F27: 29 | G27: Kaduna | H27: 44785 | I27: 8000000014 | J27: 330000 | K27: 14 | L27: First Bank | M27: =salarydata[[#This Row],[Basic Salary]]*$AC$13 -> 3300 | N27: =salarydata[[#This Row],[Basic Salary]]*$AC$14 -> 49500 | O27: =salarydata[[#This Row],[Basic Salary]]*$AC$15 -> 16500 | P27: =salarydata[[#This Row],[Basic Salary]]*$AC$16 -> 6600 | Q27: =salarydata[[#This Row],[Basic Salary]]*$AC$17 -> 6600 | R27: =salarydata[[#This Row],[Basic Salary]]+salarydata[[#This Row],[ -Performance Bonus (1%)]]+salarydata[[#This Row],[- House Allowance (15%)]]+salarydata[[#This Row],[- Transport Allowance (5%)]]+salarydata[[#This Row],[- wordrope Allowance (2%)]]+salarydata[[#This Row],[- Over Time(2%)]] -> 412500 | S27: =salarydata[[#This Row],[Basic Salary]]*$AC$19 -> 3300 | T27: =salarydata[[#This Row],[Basic Salary]]*tax -> 16500 | U27: =salarydata[[#This Row],[Basic Salary]]*healthinsurancepremium -> 6600 | V27: =salarydata[[#This Row],[Basic Salary]]*retirementplan -> 6600 | W27: =salarydata[[#This Row],[- Loan(1%)]]+salarydata[[#This Row],[- Tax(5%)]]+salarydata[[#This Row],[ - Health Insurance Premium(2%)]]+salarydata[[#This Row],[ - Retirement Plan(2%)]] -> 33000 | X27: =salarydata[[#This Row],[- Gross Salary]]-salarydata[[#This Row],[-Total DEDUCTION.]] -> 379500 | Y27: =DATEDIF(salarydata[[#This Row],[Hire Date]], TODAY(), "Y") -> 4
A28: MDT010 | B28: Sarah | C28: Mohammed | D28: HR | E28: Female | F28: 30 | G28: Abuja | H28: 44402 | I28: 8000000010 | J28: 340000 | K28: 10 | L28: UBA | M28: =salarydata[[#This Row],[Basic Salary]]*$AC$13 -> 3400 | N28: =salarydata[[#This Row],[Basic Salary]]*$AC$14 -> 51000 | O28: =salarydata[[#This Row],[Basic Salary]]*$AC$15 -> 17000 | P28: =salarydata[[#This Row],[Basic Salary]]*$AC$16 -> 6800 | Q28: =salarydata[[#This Row],[Basic Salary]]*$AC$17 -> 6800 | R28: =salarydata[[#This Row],[Basic Salary]]+salarydata[[#This Row],[ -Performance Bonus (1%)]]+salarydata[[#This Row],[- House Allowance (15%)]]+salarydata[[#This Row],[- Transport Allowance (5%)]]+salarydata[[#This Row],[- wordrope Allowance (2%)]]+salarydata[[#This Row],[- Over Time(2%)]] -> 425000 | S28: =salarydata[[#This Row],[Basic Salary]]*$AC$19 -> 3400 | T28: =salarydata[[#This Row],[Basic Salary]]*tax -> 17000 | U28: =salarydata[[#This Row],[Basic Salary]]*healthinsurancepremium -> 6800 | V28: =salarydata[[#This Row],[Basic Salary]]*retirementplan -> 6800 | W28: =salarydata[[#This Row],[- Loan(1%)]]+salarydata[[#This Row],[- Tax(5%)]]+salarydata[[#This Row],[ - Health Insurance Premium(2%)]]+salarydata[[#This Row],[ - Retirement Plan(2%)]] -> 34000 | X28: =salarydata[[#This Row],[- Gross Salary]]-salarydata[[#This Row],[-Total DEDUCTION.]] -> 391000 | Y28: =DATEDIF(salarydata[[#This Row],[Hire Date]], TODAY(), "Y") -> 5
A29: MDT036 | B29: Susan | C29: Adeola | D29: Sales | E29: Female | F29: 41 | G29: Ogun | H29: 42760 | I29: 8000000036 | J29: 340000 | K29: 36 | L29: First Bank | M29: =salarydata[[#This Row],[Basic Salary]]*$AC$13 -> 3400 | N29: =salarydata[[#This Row],[Basic Salary]]*$AC$14 -> 51000 | O29: =salarydata[[#This Row],[Basic Salary]]*$AC$15 -> 17000 | P29: =salarydata[[#This Row],[Basic Salary]]*$AC$16 -> 6800 | Q29: =salarydata[[#This Row],[Basic Salary]]*$AC$17 -> 6800 | R29: =salarydata[[#This Row],[Basic Salary]]+salarydata[[#This Row],[ -Performance Bonus (1%)]]+salarydata[[#This Row],[- House Allowance (15%)]]+salarydata[[#This Row],[- Transport Allowance (5%)]]+salarydata[[#This Row],[- wordrope Allowance (2%)]]+salarydata[[#This Row],[- Over Time(2%)]] -> 425000 | S29: =salarydata[[#This Row],[Basic Salary]]*$AC$19 -> 3400 | T29: =salarydata[[#This Row],[Basic Salary]]*tax -> 17000 | U29: =salarydata[[#This Row],[Basic Salary]]*healthinsurancepremium -> 6800 | V29: =salarydata[[#This Row],[Basic Salary]]*retirementplan -> 6800 | W29: =salarydata[[#This Row],[- Loan(1%)]]+salarydata[[#This Row],[- Tax(5%)]]+salarydata[[#This Row],[ - Health Insurance Premium(2%)]]+salarydata[[#This Row],[ - Retirement Plan(2%)]] -> 34000 | X29: =salarydata[[#This Row],[- Gross Salary]]-salarydata[[#This Row],[-Total DEDUCTION.]] -> 391000 | Y29: =DATEDIF(salarydata[[#This Row],[Hire Date]], TODAY(), "Y") -> 9
A30: MDT030 | B30: Naomi | C30: Abubakar | D30: Marketing | E30: Female | F30: 37 | G30: Kaduna | H30: 43230 | I30: 8000000030 | J30: 345000 | K30: 30 | L30: First Bank | M30: =salarydata[[#This Row],[Basic Salary]]*$AC$13 -> 3450 | N30: =salarydata[[#This Row],[Basic Salary]]*$AC$14 -> 51750 | O30: =salarydata[[#This Row],[Basic Salary]]*$AC$15 -> 17250 | P30: =salarydata[[#This Row],[Basic Salary]]*$AC$16 -> 6900 | Q30: =salarydata[[#This Row],[Basic Salary]]*$AC$17 -> 6900 | R30: =salarydata[[#This Row],[Basic Salary]]+salarydata[[#This Row],[ -Performance Bonus (1%)]]+salarydata[[#This Row],[- House Allowance (15%)]]+salarydata[[#This Row],[- Transport Allowance (5%)]]+salarydata[[#This Row],[- wordrope Allowance (2%)]]+salarydata[[#This Row],[- Over Time(2%)]] -> 431250 | S30: =salarydata[[#This Row],[Basic Salary]]*$AC$19 -> 3450 | T30: =salarydata[[#This Row],[Basic Salary]]*tax -> 17250 | U30: =salarydata[[#This Row],[Basic Salary]]*healthinsurancepremium -> 6900 | V30: =salarydata[[#This Row],[Basic Salary]]*retirementplan -> 6900 | W30: =salarydata[[#This Row],[- Loan(1%)]]+salarydata[[#This Row],[- Tax(5%)]]+salarydata[[#This Row],[ - Health Insurance Premium(2%)]]+salarydata[[#This Row],[ - Retirement Plan(2%)]] -> 34500 | X30: =salarydata[[#This Row],[- Gross Salary]]-salarydata[[#This Row],[-Total DEDUCTION.]] -> 396750 | Y30: =DATEDIF(salarydata[[#This Row],[Hire Date]], TODAY(), "Y") -> 8
A31: MDT007 | B31: David | C31: Yusuf | D31: Marketing | E31: Male | F31: 35 | G31: Kano | H31: 44092 | I31: 8000000007 | J31: 350000 | K31: 7 | L31: GTBank | M31: =salarydata[[#This Row],[Basic Salary]]*$AC$13 -> 3500 | N31: =salarydata[[#This Row],[Basic Salary]]*$AC$14 -> 52500 | O31: =salarydata[[#This Row],[Basic Salary]]*$AC$15 -> 17500 | P31: =salarydata[[#This Row],[Basic Salary]]*$AC$16 -> 7000 | Q31: =salarydata[[#This Row],[Basic Salary]]*$AC$17 -> 7000 | R31: =salarydata[[#This Row],[Basic Salary]]+salarydata[[#This Row],[ -Performance Bonus (1%)]]+salarydata[[#This Row],[- House Allowance (15%)]]+salarydata[[#This Row],[- Transport Allowance (5%)]]+salarydata[[#This Row],[- wordrope Allowance (2%)]]+salarydata[[#This Row],[- Over Time(2%)]] -> 437500 | S31: =salarydata[[#This Row],[Basic Salary]]*$AC$19 -> 3500 | T31: =salarydata[[#This Row],[Basic Salary]]*tax -> 17500 | U31: =salarydata[[#This Row],[Basic Salary]]*healthinsurancepremium -> 7000 | V31: =salarydata[[#This Row],[Basic Salary]]*retirementplan -> 7000 | W31: =salarydata[[#This Row],[- Loan(1%)]]+salarydata[[#This Row],[- Tax(5%)]]+salarydata[[#This Row],[ - Health Insurance Premium(2%)]]+salarydata[[#This Row],[ - Retirement Plan(2%)]] -> 35000 | X31: =salarydata[[#This Row],[- Gross Salary]]-salarydata[[#This Row],[-Total DEDUCTION.]] -> 402500 | Y31: =DATEDIF(salarydata[[#This Row],[Hire Date]], TODAY(), "Y") -> 5
A32: MDT034 | B32: Florence | C32: Musa | D32: HR | E32: Female | F32: 28 | G32: Kano | H32: 44988 | I32: 8000000034 | J32: 350000 | K32: 34 | L32: GTBank | M32: =salarydata[[#This Row],[Basic Salary]]*$AC$13 -> 3500 | N32: =salarydata[[#This Row],[Basic Salary]]*$AC$14 -> 52500 | O32: =salarydata[[#This Row],[Basic Salary]]*$AC$15 -> 17500 | P32: =salarydata[[#This Row],[Basic Salary]]*$AC$16 -> 7000 | Q32: =salarydata[[#This Row],[Basic Salary]]*$AC$17 -> 7000 | R32: =salarydata[[#This Row],[Basic Salary]]+salarydata[[#This Row],[ -Performance Bonus (1%)]]+salarydata[[#This Row],[- House Allowance (15%)]]+salarydata[[#This Row],[- Transport Allowance (5%)]]+salarydata[[#This Row],[- wordrope Allowance (2%)]]+salarydata[[#This Row],[- Over Time(2%)]] -> 437500 | S32: =salarydata[[#This Row],[Basic Salary]]*$AC$19 -> 3500 | T32: =salarydata[[#This Row],[Basic Salary]]*tax -> 17500 | U32: =salarydata[[#This Row],[Basic Salary]]*healthinsurancepremium -> 7000 | V32: =salarydata[[#This Row],[Basic Salary]]*retirementplan -> 7000 | W32: =salarydata[[#This Row],[- Loan(1%)]]+salarydata[[#This Row],[- Tax(5%)]]+salarydata[[#This Row],[ - Health Insurance Premium(2%)]]+salarydata[[#This Row],[ - Retirement Plan(2%)]] -> 35000 | X32: =salarydata[[#This Row],[- Gross Salary]]-salarydata[[#This Row],[-Total DEDUCTION.]] -> 402500 | Y32: =DATEDIF(salarydata[[#This Row],[Hire Date]], TODAY(), "Y") -> 3
... A51: MDT033 | B51: Anthony | C51: Obi | D51: ICT | E51: Male | F51: 43 | G51: Anambra | H51: 42507 | I51: 8000000033 | J51: 600000 | K51: 33 | L51: Zenith Bank | M51: =salarydata[[#This Row],[Basic Salary]]*$AC$13 -> 6000 | N51: =salarydata[[#This Row],[Basic Salary]]*$AC$14 -> 90000 | O51: =salarydata[[#This Row],[Basic Salary]]*$AC$15 -> 30000 | P51: =salarydata[[#This Row],[Basic Salary]]*$AC$16 -> 12000 | Q51: =salarydata[[#This Row],[Basic Salary]]*$AC$17 -> 12000 | R51: =salarydata[[#This Row],[Basic Salary]]+salarydata[[#This Row],[ -Performance Bonus (1%)]]+salarydata[[#This Row],[- House Allowance (15%)]]+salarydata[[#This Row],[- Transport Allowance (5%)]]+salarydata[[#This Row],[- wordrope Allowance (2%)]]+salarydata[[#This Row],[- Over Time(2%)]] -> 750000 | S51: =salarydata[[#This Row],[Basic Salary]]*$AC$19 -> 6000 | T51: =salarydata[[#This Row],[Basic Salary]]*tax -> 30000 | U51: =salarydata[[#This Row],[Basic Salary]]*healthinsurancepremium -> 12000 | V51: =salarydata[[#This Row],[Basic Salary]]*retirementplan -> 12000 | W51: =salarydata[[#This Row],[- Loan(1%)]]+salarydata[[#This Row],[- Tax(5%)]]+salarydata[[#This Row],[ - Health Insurance Premium(2%)]]+salarydata[[#This Row],[ - Retirement Plan(2%)]] -> 60000 | X51: =salarydata[[#This Row],[- Gross Salary]]-salarydata[[#This Row],[-Total DEDUCTION.]] -> 690000 | Y51: =DATEDIF(salarydata[[#This Row],[Hire Date]], TODAY(), "Y") -> 10

Sheet employe benefit
A1: employe benefits | B1: Column1
A2: -Performance Bonus (1%) | B2: 0.01
A3: - House Allowance (15%) | B3: 0.15
A4: - Transport Allowance (5%) | B4: 0.05
A5: - wordrope Allowance (2%) | B5: 0.02
A6: - Over Time(2%) | B6: 0.02
A7: - Gross Salary
A8: - Loan(1%) | B8: 0.01
A9: - Tax(5%) | B9: 0.05
A11: - Health Insurance Premium(2%) | B11: 0.02
A12: - Retirement Plan(2%) | B12: 0.02
A13: -Total DEDUCTION.
A14: -NET SALARY

Sheet kpi
A1: KPI | B1: VALUES
A2: Total Deduction | B2: =SUM(salarydata[-Total DEDUCTION.]) -> 1722000
A3: Total Gross Payroll | B3: =SUM(salarydata[- Gross Salary]) -> 21525000
A4: Total Net Payroll | B4: =SUM(salarydata[-NET SALARY ]) -> 19803000
A5: Average Salary | B5: =AVERAGE(salarydata!J8:J51) -> 365000
A6: Lowest Salary Earner | B6: =MIN(salarydata[Basic Salary]) -> 180000
A7: Highest Salary | B7: =MAX(salarydata[Basic Salary]) -> 600000
A8: Total Employee | B8: =ROWS(salarydata[]) -> 50
A9: least salary | B9: =MIN(salarydata[Basic Salary]) -> 180000
A12: basic salary | B12: =SUM(salarydata[Basic Salary]) -> 17220000
A13: Avg Female basic salary | B13: =AVERAGEIF(salarydata[Gender],"Female",salarydata[Basic Salary]) -> 304400
A14: Avg Male basic salary | B14: =AVERAGEIF(salarydata[Gender], "Male",salarydata[Basic Salary]) -> 384400
A15: Avg employee tenure | B15: =AVERAGE(salarydata[employee tenure]) -> 5.76

Sheet dashboard with interactive kpi
B7: =GETPIVOTDATA("Sum of -Total DEDUCTION.",pivot!$A$3) -> 1722000 | F7: =GETPIVOTDATA("Sum of - Gross Salary",pivot!$A$3) -> 21525000 | K7: =GETPIVOTDATA("Sum of -NET SALARY ",pivot!$A$3) -> 19803000 | P7: =GETPIVOTDATA("Average of Basic Salary",pivot!$A$3) -> 344400 | U7: =GETPIVOTDATA("Count of Employee ID",pivot!$A$3) -> 50
